ERROR:root:Exception occurred
Traceback (most recent call last):
  File "/home/max/Documents/death-clock/stoic-clock/venv/lib/python3.6/site-packages/urllib3/connection.py", line 160, in _new_conn
    (self._dns_host, self.port), self.timeout, **extra_kw
  File "/home/max/Documents/death-clock/stoic-clock/venv/lib/python3.6/site-packages/urllib3/util/connection.py", line 84, in create_connection
    raise err
  File "/home/max/Documents/death-clock/stoic-clock/venv/lib/python3.6/site-packages/urllib3/util/connection.py", line 74, in create_connection
    sock.connect(sa)
ConnectionRefusedError: [Errno 111] Connection refused

During handling of the above exception, another exception occurred:

Traceback (most recent call last):
  File "/home/max/Documents/death-clock/stoic-clock/venv/lib/python3.6/site-packages/urllib3/connectionpool.py", line 677, in urlopen
    chunked=chunked,
  File "/home/max/Documents/death-clock/stoic-clock/venv/lib/python3.6/site-packages/urllib3/connectionpool.py", line 392, in _make_request
    conn.request(method, url, **httplib_request_kw)
  File "/usr/lib/python3.6/http/client.py", line 1264, in request
    self._send_request(method, url, body, headers, encode_chunked)
  File "/usr/lib/python3.6/http/client.py", line 1310, in _send_request
    self.endheaders(body, encode_chunked=encode_chunked)
  File "/usr/lib/python3.6/http/client.py", line 1259, in endheaders
    self._send_output(message_body, encode_chunked=encode_chunked)
  File "/usr/lib/python3.6/http/client.py", line 1038, in _send_output
    self.send(msg)
  File "/usr/lib/python3.6/http/client.py", line 976, in send
    self.connect()
  File "/home/max/Documents/death-clock/stoic-clock/venv/lib/python3.6/site-packages/urllib3/connection.py", line 187, in connect
    conn = self._new_conn()
  File "/home/max/Documents/death-clock/stoic-clock/venv/lib/python3.6/site-packages/urllib3/connection.py", line 172, in _new_conn
    self, "Failed to establish a new connection: %s" % e
urllib3.exceptions.NewConnectionError: <urllib3.connection.HTTPConnection object at 0x7f3ac4087748>: Failed to establish a new connection: [Errno 111] Connection refused

During handling of the above exception, another exception occurred:

Traceback (most recent call last):
  File "/home/max/Documents/death-clock/stoic-clock/venv/lib/python3.6/site-packages/requests/adapters.py", line 449, in send
    timeout=timeout
  File "/home/max/Documents/death-clock/stoic-clock/venv/lib/python3.6/site-packages/urllib3/connectionpool.py", line 725, in urlopen
    method, url, error=e, _pool=self, _stacktrace=sys.exc_info()[2]
  File "/home/max/Documents/death-clock/stoic-clock/venv/lib/python3.6/site-packages/urllib3/util/retry.py", line 439, in increment
    raise MaxRetryError(_pool, url, error or ResponseError(cause))
urllib3.exceptions.MaxRetryError: HTTPConnectionPool(host='10.0.0.79', port=5000): Max retries exceeded with url: /api/clock/AAB (Caused by NewConnectionError('<urllib3.connection.HTTPConnection object at 0x7f3ac4087748>: Failed to establish a new connection: [Errno 111] Connection refused',))

During handling of the above exception, another exception occurred:

Traceback (most recent call last):
  File "/home/max/Documents/death-clock/stoic-clock/api.py", line 35, in run
    r = requests.get(self.website + self.clock_id)
  File "/home/max/Documents/death-clock/stoic-clock/venv/lib/python3.6/site-packages/requests/api.py", line 76, in get
    return request('get', url, params=params, **kwargs)
  File "/home/max/Documents/death-clock/stoic-clock/venv/lib/python3.6/site-packages/requests/api.py", line 61, in request
    return session.request(method=method, url=url, **kwargs)
  File "/home/max/Documents/death-clock/stoic-clock/venv/lib/python3.6/site-packages/requests/sessions.py", line 530, in request
    resp = self.send(prep, **send_kwargs)
  File "/home/max/Documents/death-clock/stoic-clock/venv/lib/python3.6/site-packages/requests/sessions.py", line 643, in send
    r = adapter.send(request, **kwargs)
  File "/home/max/Documents/death-clock/stoic-clock/venv/lib/python3.6/site-packages/requests/adapters.py", line 516, in send
    raise ConnectionError(e, request=request)
requests.exceptions.ConnectionError: HTTPConnectionPool(host='10.0.0.79', port=5000): Max retries exceeded with url: /api/clock/AAB (Caused by NewConnectionError('<urllib3.connection.HTTPConnection object at 0x7f3ac4087748>: Failed to establish a new connection: [Errno 111] Connection refused',))
