ERROR:root:Exception occurred
Traceback (most recent call last):
  File "/home/max/Documents/death-clock/stoic-clock/api.py", line 35, in run
    self.settings = r.json()
  File "/home/max/Documents/death-clock/stoic-clock/venv/lib/python3.6/site-packages/requests/models.py", line 898, in json
    return complexjson.loads(self.text, **kwargs)
  File "/usr/lib/python3.6/json/__init__.py", line 354, in loads
    return _default_decoder.decode(s)
  File "/usr/lib/python3.6/json/decoder.py", line 339, in decode
    obj, end = self.raw_decode(s, idx=_w(s, 0).end())
  File "/usr/lib/python3.6/json/decoder.py", line 357, in raw_decode
    raise JSONDecodeError("Expecting value", s, err.value) from None
json.decoder.JSONDecodeError: Expecting value: line 1 column 1 (char 0)
ERROR:root:Exception occurred
Traceback (most recent call last):
  File "/home/max/Documents/death-clock/stoic-clock/api.py", line 35, in run
    self.settings = r.json()
  File "/home/max/Documents/death-clock/stoic-clock/venv/lib/python3.6/site-packages/requests/models.py", line 898, in json
    return complexjson.loads(self.text, **kwargs)
  File "/usr/lib/python3.6/json/__init__.py", line 354, in loads
    return _default_decoder.decode(s)
  File "/usr/lib/python3.6/json/decoder.py", line 339, in decode
    obj, end = self.raw_decode(s, idx=_w(s, 0).end())
  File "/usr/lib/python3.6/json/decoder.py", line 357, in raw_decode
    raise JSONDecodeError("Expecting value", s, err.value) from None
json.decoder.JSONDecodeError: Expecting value: line 1 column 1 (char 0)
ERROR:root:Exception occurred
Traceback (most recent call last):
  File "/home/max/Documents/death-clock/stoic-clock/api.py", line 35, in run
    self.settings = r.json()
  File "/home/max/Documents/death-clock/stoic-clock/venv/lib/python3.6/site-packages/requests/models.py", line 898, in json
    return complexjson.loads(self.text, **kwargs)
  File "/usr/lib/python3.6/json/__init__.py", line 354, in loads
    return _default_decoder.decode(s)
  File "/usr/lib/python3.6/json/decoder.py", line 339, in decode
    obj, end = self.raw_decode(s, idx=_w(s, 0).end())
  File "/usr/lib/python3.6/json/decoder.py", line 357, in raw_decode
    raise JSONDecodeError("Expecting value", s, err.value) from None
json.decoder.JSONDecodeError: Expecting value: line 1 column 1 (char 0)
ERROR:root:Exception occurred
Traceback (most recent call last):
  File "/home/max/Documents/death-clock/stoic-clock/api.py", line 35, in run
    self.settings = r.json()
  File "/home/max/Documents/death-clock/stoic-clock/venv/lib/python3.6/site-packages/requests/models.py", line 898, in json
    return complexjson.loads(self.text, **kwargs)
  File "/usr/lib/python3.6/json/__init__.py", line 354, in loads
    return _default_decoder.decode(s)
  File "/usr/lib/python3.6/json/decoder.py", line 339, in decode
    obj, end = self.raw_decode(s, idx=_w(s, 0).end())
  File "/usr/lib/python3.6/json/decoder.py", line 357, in raw_decode
    raise JSONDecodeError("Expecting value", s, err.value) from None
json.decoder.JSONDecodeError: Expecting value: line 1 column 1 (char 0)
ERROR:root:Exception occurred
Traceback (most recent call last):
  File "/home/max/Documents/death-clock/stoic-clock/api.py", line 35, in run
    self.settings = r.json()
  File "/home/max/Documents/death-clock/stoic-clock/venv/lib/python3.6/site-packages/requests/models.py", line 898, in json
    return complexjson.loads(self.text, **kwargs)
  File "/usr/lib/python3.6/json/__init__.py", line 354, in loads
    return _default_decoder.decode(s)
  File "/usr/lib/python3.6/json/decoder.py", line 339, in decode
    obj, end = self.raw_decode(s, idx=_w(s, 0).end())
  File "/usr/lib/python3.6/json/decoder.py", line 357, in raw_decode
    raise JSONDecodeError("Expecting value", s, err.value) from None
json.decoder.JSONDecodeError: Expecting value: line 1 column 1 (char 0)
ERROR:root:Exception occurred
Traceback (most recent call last):
  File "/home/max/Documents/death-clock/stoic-clock/api.py", line 35, in run
    self.settings = r.json()
  File "/home/max/Documents/death-clock/stoic-clock/venv/lib/python3.6/site-packages/requests/models.py", line 898, in json
    return complexjson.loads(self.text, **kwargs)
  File "/usr/lib/python3.6/json/__init__.py", line 354, in loads
    return _default_decoder.decode(s)
  File "/usr/lib/python3.6/json/decoder.py", line 339, in decode
    obj, end = self.raw_decode(s, idx=_w(s, 0).end())
  File "/usr/lib/python3.6/json/decoder.py", line 357, in raw_decode
    raise JSONDecodeError("Expecting value", s, err.value) from None
json.decoder.JSONDecodeError: Expecting value: line 1 column 1 (char 0)
ERROR:root:Exception occurred
Traceback (most recent call last):
  File "/home/max/Documents/death-clock/stoic-clock/api.py", line 35, in run
    self.settings = r.json()
  File "/home/max/Documents/death-clock/stoic-clock/venv/lib/python3.6/site-packages/requests/models.py", line 898, in json
    return complexjson.loads(self.text, **kwargs)
  File "/usr/lib/python3.6/json/__init__.py", line 354, in loads
    return _default_decoder.decode(s)
  File "/usr/lib/python3.6/json/decoder.py", line 339, in decode
    obj, end = self.raw_decode(s, idx=_w(s, 0).end())
  File "/usr/lib/python3.6/json/decoder.py", line 357, in raw_decode
    raise JSONDecodeError("Expecting value", s, err.value) from None
json.decoder.JSONDecodeError: Expecting value: line 1 column 1 (char 0)
ERROR:root:Exception occurred
Traceback (most recent call last):
  File "/home/max/Documents/death-clock/stoic-clock/api.py", line 35, in run
    self.settings = r.json()
  File "/home/max/Documents/death-clock/stoic-clock/venv/lib/python3.6/site-packages/requests/models.py", line 898, in json
    return complexjson.loads(self.text, **kwargs)
  File "/usr/lib/python3.6/json/__init__.py", line 354, in loads
    return _default_decoder.decode(s)
  File "/usr/lib/python3.6/json/decoder.py", line 339, in decode
    obj, end = self.raw_decode(s, idx=_w(s, 0).end())
  File "/usr/lib/python3.6/json/decoder.py", line 357, in raw_decode
    raise JSONDecodeError("Expecting value", s, err.value) from None
json.decoder.JSONDecodeError: Expecting value: line 1 column 1 (char 0)
ERROR:root:Exception occurred
Traceback (most recent call last):
  File "/home/max/Documents/death-clock/stoic-clock/api.py", line 35, in run
    self.settings = r.json()
  File "/home/max/Documents/death-clock/stoic-clock/venv/lib/python3.6/site-packages/requests/models.py", line 898, in json
    return complexjson.loads(self.text, **kwargs)
  File "/usr/lib/python3.6/json/__init__.py", line 354, in loads
    return _default_decoder.decode(s)
  File "/usr/lib/python3.6/json/decoder.py", line 339, in decode
    obj, end = self.raw_decode(s, idx=_w(s, 0).end())
  File "/usr/lib/python3.6/json/decoder.py", line 357, in raw_decode
    raise JSONDecodeError("Expecting value", s, err.value) from None
json.decoder.JSONDecodeError: Expecting value: line 1 column 1 (char 0)
ERROR:root:Exception occurred
Traceback (most recent call last):
  File "/home/max/Documents/death-clock/stoic-clock/api.py", line 35, in run
    self.settings = r.json()
  File "/home/max/Documents/death-clock/stoic-clock/venv/lib/python3.6/site-packages/requests/models.py", line 898, in json
    return complexjson.loads(self.text, **kwargs)
  File "/usr/lib/python3.6/json/__init__.py", line 354, in loads
    return _default_decoder.decode(s)
  File "/usr/lib/python3.6/json/decoder.py", line 339, in decode
    obj, end = self.raw_decode(s, idx=_w(s, 0).end())
  File "/usr/lib/python3.6/json/decoder.py", line 357, in raw_decode
    raise JSONDecodeError("Expecting value", s, err.value) from None
json.decoder.JSONDecodeError: Expecting value: line 1 column 1 (char 0)
ERROR:root:Exception occurred
Traceback (most recent call last):
  File "/home/max/Documents/death-clock/stoic-clock/api.py", line 35, in run
    self.settings = r.json()
  File "/home/max/Documents/death-clock/stoic-clock/venv/lib/python3.6/site-packages/requests/models.py", line 898, in json
    return complexjson.loads(self.text, **kwargs)
  File "/usr/lib/python3.6/json/__init__.py", line 354, in loads
    return _default_decoder.decode(s)
  File "/usr/lib/python3.6/json/decoder.py", line 339, in decode
    obj, end = self.raw_decode(s, idx=_w(s, 0).end())
  File "/usr/lib/python3.6/json/decoder.py", line 357, in raw_decode
    raise JSONDecodeError("Expecting value", s, err.value) from None
json.decoder.JSONDecodeError: Expecting value: line 1 column 1 (char 0)
ERROR:root:Exception occurred
Traceback (most recent call last):
  File "/home/max/Documents/death-clock/stoic-clock/api.py", line 35, in run
    self.settings = r.json()
  File "/home/max/Documents/death-clock/stoic-clock/venv/lib/python3.6/site-packages/requests/models.py", line 898, in json
    return complexjson.loads(self.text, **kwargs)
  File "/usr/lib/python3.6/json/__init__.py", line 354, in loads
    return _default_decoder.decode(s)
  File "/usr/lib/python3.6/json/decoder.py", line 339, in decode
    obj, end = self.raw_decode(s, idx=_w(s, 0).end())
  File "/usr/lib/python3.6/json/decoder.py", line 357, in raw_decode
    raise JSONDecodeError("Expecting value", s, err.value) from None
json.decoder.JSONDecodeError: Expecting value: line 1 column 1 (char 0)
